<?xml version="1.0" ?>
<sdf version="1.6">
  <world name="default">

    <gui>
      <plugin name="simslides" filename="libsimslides.so">
        <slide_prefix>slide</slide_prefix>
      </plugin>
      <plugin name="keyboard" filename="libKeyboardGUIPlugin.so">
      </plugin>
      <camera name='user_camera'>
        <pose frame=''>14.4 15.14 13.21 0 0.22 -2.24</pose>
      </camera>
    </gui>
    <scene>
      <grid>0</grid>
      <origin_visual>0</origin_visual>
      <sky/>
      <ambient>0.4 0.4 0.4 1</ambient>
      <background>0.7 0.7 0.7 1</background>
      <shadows>1</shadows>
    </scene>

    <!-- A global light source -->
    <light name='sun' type='directional'>
      <cast_shadows>1</cast_shadows>
      <pose frame=''>0 0 -1 -0.6 0.11 0.08</pose>
      <diffuse>0.8 0.8 0.8 1</diffuse>
      <specular>0.2 0.2 0.2 1</specular>
      <attenuation>
        <range>1000</range>
        <constant>0.9</constant>
        <linear>0.01</linear>
        <quadratic>0.001</quadratic>
      </attenuation>
      <direction>-0.5 0.1 -0.9</direction>
    </light>

    <!-- factory -->
    <include>
      <uri>model://workcell</uri>
    </include>

    <!-- person -->
    <actor name='actor'>
      <skin>
        <filename>talk_b.dae</filename>
        <scale>1</scale>
      </skin>
      <animation name="animation">
        <filename>talk_b.dae</filename>
      </animation>
      <script>
        <trajectory id="0" type="animation">
          <waypoint>
            <time>100</time>
            <pose>-1.329 -0.368 0 0 0 0.846</pose>
          </waypoint>
          <waypoint>
            <time>100</time>
            <pose>-1.329 -0.368 0 0 0 0.846</pose>
          </waypoint>
        </trajectory>
      </script>
    </actor>

    <include>
      <pose>10 10 10.34 0 0 2.4755</pose>
      <uri>model://slide-0</uri>
    </include>

    <include>
      <pose>15.92 -2.355 2.869 0 0 1.57</pose>
      <uri>model://slide-1</uri>
    </include>

    <include>
      <pose>-2.071 -3.869 2.61 0 0 3.14</pose>
      <uri>model://slide-2</uri>
    </include>

    <include>
      <pose>-2.071 -3.869 2.61 0 0 3.14</pose>
      <uri>model://slide-3</uri>
    </include>

    <include>
      <pose>-2.071 -3.869 2.61 0 0 3.14</pose>
      <uri>model://slide-4</uri>
    </include>

    <include>
      <pose>-2.071 -3.869 2.61 0 0 3.14</pose>
      <uri>model://slide-5</uri>
    </include>

    <include>
      <pose>-2.071 -3.869 2.61 0 0 3.14</pose>
      <uri>model://slide-6</uri>
    </include>

    <include>
      <pose>-2.071 -3.869 2.61 0 0 3.14</pose>
      <uri>model://slide-7</uri>
    </include>

    <include>
      <pose>-3.74 8.82 0 0 0 2.63222</pose>
      <uri>model://slide-8</uri>
    </include>

    <include>
      <pose>-10 20 8.22 0 0 -3.14</pose>
      <uri>model://slide-9</uri>
    </include>

    <include>
      <pose>-11.97 25.822 0 0 0 -2.79</pose>
      <uri>model://slide-10</uri>
    </include>

    <!-- UR10 -->
    <model name='ur10'>
      <pose frame=''>0.11 -0.38 0.78 0 0 0</pose>
      <link name='base'>
        <inertial>
          <mass>4</mass>
          <inertia>
            <ixx>0.00610633</ixx>
            <ixy>0</ixy>
            <ixz>0</ixz>
            <iyy>0.00610633</iyy>
            <iyz>0</iyz>
            <izz>0.01125</izz>
          </inertia>
        </inertial>
        <collision name='collision'>
          <pose frame=''>0 0 0.019 0 -0 0</pose>
          <geometry>
            <cylinder>
              <radius>0.075</radius>
              <length>0.038</length>
            </cylinder>
          </geometry>
          <max_contacts>10</max_contacts>
          <surface>
            <contact>
              <ode/>
            </contact>
            <bounce/>
            <friction>
              <torsional>
                <ode/>
              </torsional>
              <ode/>
            </friction>
          </surface>
        </collision>
        <visual name='visual'>
          <geometry>
            <mesh>
              <uri>model://ur10/meshes/base.dae</uri>
              <scale>1 1 1</scale>
            </mesh>
          </geometry>
        </visual>
        <self_collide>0</self_collide>
        <enable_wind>0</enable_wind>
        <kinematic>0</kinematic>
      </link>
      <link name='shoulder'>
        <pose frame=''>0 0 0.1273 0 -0 0</pose>
        <inertial>
          <mass>7.778</mass>
          <inertia>
            <ixx>0.0314743</ixx>
            <ixy>0</ixy>
            <ixz>0</ixz>
            <iyy>0.0314743</iyy>
            <iyz>0</iyz>
            <izz>0.0218756</izz>
          </inertia>
        </inertial>
        <collision name='collision'>
          <geometry>
            <cylinder>
              <radius>0.075</radius>
              <length>0.177</length>
            </cylinder>
          </geometry>
          <max_contacts>10</max_contacts>
          <surface>
            <contact>
              <ode/>
            </contact>
            <bounce/>
            <friction>
              <torsional>
                <ode/>
              </torsional>
              <ode/>
            </friction>
          </surface>
        </collision>
        <visual name='visual'>
          <geometry>
            <mesh>
              <uri>model://ur10/meshes/shoulder.dae</uri>
              <scale>1 1 1</scale>
            </mesh>
          </geometry>
        </visual>
        <self_collide>0</self_collide>
        <enable_wind>0</enable_wind>
        <kinematic>0</kinematic>
      </link>
      <link name='upper_arm'>
        <pose frame=''>0 0.220941 0.1273 3.14159 1.57079 3.14159</pose>
        <inertial>
          <pose frame=''>0 0 0.306 0 -0 0</pose>
          <mass>12.93</mass>
          <inertia>
            <ixx>0.421754</ixx>
            <ixy>0</ixy>
            <ixz>0</ixz>
            <iyy>0.421754</iyy>
            <iyz>0</iyz>
            <izz>0.0363656</izz>
          </inertia>
        </inertial>
        <collision name='collision1'>
          <pose frame=''>0 -0.045 0 1.5707 -0 0</pose>
          <geometry>
            <cylinder>
              <radius>0.075</radius>
              <length>0.177</length>
            </cylinder>
          </geometry>
          <max_contacts>10</max_contacts>
          <surface>
            <contact>
              <ode/>
            </contact>
            <bounce/>
            <friction>
              <torsional>
                <ode/>
              </torsional>
              <ode/>
            </friction>
          </surface>
        </collision>
        <collision name='collision2'>
          <pose frame=''>0 -0.0436 0.32 0 -0 1.5707</pose>
          <geometry>
            <cylinder>
              <radius>0.058</radius>
              <length>0.461</length>
            </cylinder>
          </geometry>
          <max_contacts>10</max_contacts>
          <surface>
            <contact>
              <ode/>
            </contact>
            <bounce/>
            <friction>
              <torsional>
                <ode/>
              </torsional>
              <ode/>
            </friction>
          </surface>
        </collision>
        <collision name='collision3'>
          <pose frame=''>0 -0.04 0.613 1.5707 -0 0</pose>
          <geometry>
            <cylinder>
              <radius>0.058</radius>
              <length>0.129</length>
            </cylinder>
          </geometry>
          <max_contacts>10</max_contacts>
          <surface>
            <contact>
              <ode/>
            </contact>
            <bounce/>
            <friction>
              <torsional>
                <ode/>
              </torsional>
              <ode/>
            </friction>
          </surface>
        </collision>
        <visual name='visual'>
          <geometry>
            <mesh>
              <uri>model://ur10/meshes/upperarm.dae</uri>
              <scale>1 1 1</scale>
            </mesh>
          </geometry>
        </visual>
        <self_collide>0</self_collide>
        <enable_wind>0</enable_wind>
        <kinematic>0</kinematic>
      </link>
      <link name='forearm'>
        <pose frame=''>0.612 0.049041 0.1273 3.14159 1.57079 3.14159</pose>
        <inertial>
          <pose frame=''>0 0 0.28615 0 -0 0</pose>
          <mass>3.87</mass>
          <inertia>
            <ixx>0.11107</ixx>
            <ixy>0</ixy>
            <ixz>0</ixz>
            <iyy>0.11107</iyy>
            <iyz>0</iyz>
            <izz>0.0108844</izz>
          </inertia>
        </inertial>
        <collision name='collision1'>
          <pose frame=''>0 0 0.001 1.5707 -0 0</pose>
          <geometry>
            <cylinder>
              <radius>0.058</radius>
              <length>0.136</length>
            </cylinder>
          </geometry>
          <max_contacts>10</max_contacts>
          <surface>
            <contact>
              <ode/>
            </contact>
            <bounce/>
            <friction>
              <torsional>
                <ode/>
              </torsional>
              <ode/>
            </friction>
          </surface>
        </collision>
        <collision name='collision2'>
          <pose frame=''>0 0 0.305 0 -0 1.5707</pose>
          <geometry>
            <cylinder>
              <radius>0.045</radius>
              <length>0.447</length>
            </cylinder>
          </geometry>
          <max_contacts>10</max_contacts>
          <surface>
            <contact>
              <ode/>
            </contact>
            <bounce/>
            <friction>
              <torsional>
                <ode/>
              </torsional>
              <ode/>
            </friction>
          </surface>
        </collision>
        <collision name='collision3'>
          <pose frame=''>0 0.001 0.5735 1.5707 -0 0</pose>
          <geometry>
            <cylinder>
              <radius>0.045</radius>
              <length>0.119</length>
            </cylinder>
          </geometry>
          <max_contacts>10</max_contacts>
          <surface>
            <contact>
              <ode/>
            </contact>
            <bounce/>
            <friction>
              <torsional>
                <ode/>
              </torsional>
              <ode/>
            </friction>
          </surface>
        </collision>
        <visual name='visua'>
          <geometry>
            <mesh>
              <uri>model://ur10/meshes/forearm.dae</uri>
              <scale>1 1 1</scale>
            </mesh>
          </geometry>
        </visual>
        <self_collide>0</self_collide>
        <enable_wind>0</enable_wind>
        <kinematic>0</kinematic>
      </link>
      <link name='wrist_1'>
        <pose frame=''>1.1843 0.049041 0.1273 3.14159 -0 3.14159</pose>
        <inertial>
          <mass>1.96</mass>
          <inertia>
            <ixx>0.00510825</ixx>
            <ixy>0</ixy>
            <ixz>0</ixz>
            <iyy>0.00510825</iyy>
            <iyz>0</iyz>
            <izz>0.0055125</izz>
          </inertia>
        </inertial>
        <collision name='collision'>
          <pose frame=''>0 0.115 0.0025 0 -0 0</pose>
          <geometry>
            <cylinder>
              <radius>0.0455</radius>
              <length>0.119</length>
            </cylinder>
          </geometry>
          <max_contacts>10</max_contacts>
          <surface>
            <contact>
              <ode/>
            </contact>
            <bounce/>
            <friction>
              <torsional>
                <ode/>
              </torsional>
              <ode/>
            </friction>
          </surface>
        </collision>
        <visual name='visual'>
          <geometry>
            <mesh>
              <uri>model://ur10/meshes/wrist1.dae</uri>
              <scale>1 1 1</scale>
            </mesh>
          </geometry>
        </visual>
        <self_collide>0</self_collide>
        <enable_wind>0</enable_wind>
        <kinematic>0</kinematic>
      </link>
      <link name='wrist_2'>
        <pose frame=''>1.1843 0.163941 0.1273 3.14159 -0 3.14159</pose>
        <inertial>
          <mass>1.96</mass>
          <inertia>
            <ixx>0.00510825</ixx>
            <ixy>0</ixy>
            <ixz>0</ixz>
            <iyy>0.00510825</iyy>
            <iyz>0</iyz>
            <izz>0.0055125</izz>
          </inertia>
        </inertial>
        <collision name='collision'>
          <pose frame=''>0 0.002 0.11659 1.5707 -0 0</pose>
          <geometry>
            <cylinder>
              <radius>0.0455</radius>
              <length>0.119</length>
            </cylinder>
          </geometry>
          <max_contacts>10</max_contacts>
          <surface>
            <contact>
              <ode/>
            </contact>
            <bounce/>
            <friction>
              <torsional>
                <ode/>
              </torsional>
              <ode/>
            </friction>
          </surface>
        </collision>
        <visual name='visual'>
          <geometry>
            <mesh>
              <uri>model://ur10/meshes/wrist2.dae</uri>
              <scale>1 1 1</scale>
            </mesh>
          </geometry>
        </visual>
        <self_collide>0</self_collide>
        <enable_wind>0</enable_wind>
        <kinematic>0</kinematic>
      </link>
      <link name='wrist_3'>
        <pose frame=''>1.1843 0.163941 0.0116 3.14159 -0 3.14159</pose>
        <inertial>
          <mass>0.202</mass>
          <inertia>
            <ixx>0.000526462</ixx>
            <ixy>0</ixy>
            <ixz>0</ixz>
            <iyy>0.000526462</iyy>
            <iyz>0</iyz>
            <izz>0.000568125</izz>
          </inertia>
        </inertial>
        <collision name='collision'>
          <pose frame=''>0 0.0765 0 1.5707 -0 0</pose>
          <geometry>
            <cylinder>
              <radius>0.045</radius>
              <length>0.031</length>
            </cylinder>
          </geometry>
          <max_contacts>10</max_contacts>
        </collision>
        <visual name='visual'>
          <geometry>
            <mesh>
              <uri>model://ur10/meshes/wrist3.dae</uri>
              <scale>1 1 1</scale>
            </mesh>
          </geometry>
        </visual>
        <self_collide>0</self_collide>
        <enable_wind>0</enable_wind>
        <kinematic>0</kinematic>
      </link>
      <joint name='base_world' type='fixed'>
        <child>base</child>
        <parent>world</parent>
      </joint>
      <joint name='shoulder_pan' type='revolute'>
        <child>shoulder</child>
        <parent>base</parent>
        <axis>
          <xyz>0 0 1</xyz>
          <limit>
            <lower>-6.28319</lower>
            <upper>6.28319</upper>
            <effort>330</effort>
            <velocity>2.16</velocity>
          </limit>
          <use_parent_model_frame>1</use_parent_model_frame>
          <dynamics>
            <spring_reference>0</spring_reference>
            <spring_stiffness>0</spring_stiffness>
          </dynamics>
        </axis>
      </joint>
      <joint name='shoulder_lift' type='revolute'>
        <child>upper_arm</child>
        <parent>shoulder</parent>
        <axis>
          <xyz>0 1 0</xyz>
          <limit>
            <lower>-6.28319</lower>
            <upper>6.28319</upper>
            <effort>330</effort>
            <velocity>2.16</velocity>
          </limit>
          <use_parent_model_frame>1</use_parent_model_frame>
          <dynamics>
            <spring_reference>0</spring_reference>
            <spring_stiffness>0</spring_stiffness>
          </dynamics>
        </axis>
      </joint>
      <joint name='elbow' type='revolute'>
        <child>forearm</child>
        <parent>upper_arm</parent>
        <axis>
          <xyz>0 1 0</xyz>
          <limit>
            <lower>-6.28319</lower>
            <upper>6.28319</upper>
            <effort>150</effort>
            <velocity>3.15</velocity>
          </limit>
          <use_parent_model_frame>1</use_parent_model_frame>
          <dynamics>
            <spring_reference>0</spring_reference>
            <spring_stiffness>0</spring_stiffness>
          </dynamics>
        </axis>
      </joint>
      <joint name='wrist_1' type='revolute'>
        <child>wrist_1</child>
        <parent>forearm</parent>
        <axis>
          <xyz>0 1 0</xyz>
          <limit>
            <lower>-6.28319</lower>
            <upper>6.28319</upper>
            <effort>54</effort>
            <velocity>3.2</velocity>
          </limit>
          <use_parent_model_frame>1</use_parent_model_frame>
          <dynamics>
            <spring_reference>0</spring_reference>
            <spring_stiffness>0</spring_stiffness>
          </dynamics>
        </axis>
      </joint>
      <joint name='wrist_2' type='revolute'>
        <child>wrist_2</child>
        <parent>wrist_1</parent>
        <axis>
          <xyz>0 0 -1</xyz>
          <limit>
            <lower>-6.28319</lower>
            <upper>6.28319</upper>
            <effort>54</effort>
            <velocity>3.2</velocity>
          </limit>
          <use_parent_model_frame>1</use_parent_model_frame>
          <dynamics>
            <spring_reference>0</spring_reference>
            <spring_stiffness>0</spring_stiffness>
          </dynamics>
        </axis>
      </joint>
      <joint name='wrist_3' type='revolute'>
        <child>wrist_3</child>
        <parent>wrist_2</parent>
        <axis>
          <xyz>0 1 0</xyz>
          <limit>
            <lower>-6.28319</lower>
            <upper>6.28319</upper>
            <effort>54</effort>
            <velocity>3.2</velocity>
          </limit>
          <use_parent_model_frame>1</use_parent_model_frame>
          <dynamics>
            <spring_reference>0</spring_reference>
            <spring_stiffness>0</spring_stiffness>
          </dynamics>
        </axis>
      </joint>

      <plugin name='keystojoints' filename='libKeysToJointsPlugin.so'>

        <map key='121' joint='shoulder_pan' scale='-0.1' type='position' kp='1000' ki='0' kd='10'/>
        <map key='104' joint='shoulder_pan' scale='0.1' type='position' kp='1000' ki='0' kd='10'/>

        <map key='117' joint='shoulder_lift' scale='-0.1' type='position' kp='1000' ki='0' kd='10'/>
        <map key='106' joint='shoulder_lift' scale='0.1' type='position' kp='1000' ki='0' kd='10'/>

        <map key='105' joint='elbow' scale='-0.1' type='position' kp='1000' ki='0' kd='10'/>
        <map key='107' joint='elbow' scale='0.1' type='position' kp='1000' ki='0' kd='10'/>

        <map key='111' joint='wrist_1' scale='-1' type='position' kp='100' ki='0' kd='10'/>
        <map key='108' joint='wrist_1' scale='1' type='position' kp='100' ki='0' kd='10'/>

        <map key='112' joint='wrist_2' scale='-1' type='position' kp='100' ki='0' kd='10'/>
        <map key='59' joint='wrist_2' scale='1' type='position' kp='100' ki='0' kd='10'/>

        <map key='91' joint='wrist_3' scale='-1' type='position' kp='100' ki='0' kd='10'/>
        <map key='39' joint='wrist_3' scale='1' type='position' kp='100' ki='0' kd='10'/>

      </plugin>

    </model>
  </world>
</sdf>
